Workbook

Sheet IMPRIMIR
B1: CONSULTOR DE VENDAS:
B3: MÊS REFERÊNCIA
E5: FLUXO DE PORTA | G5: CARTEIRA | J5: LEADS | N5: VENDAS TOTAL
B6: DIA | E6: VENDAS | F6: VISITAS | G6: VENDAS | H6: VISITAS | I6: AGENDAMENTOS | J6: VENDA | K6: VISITAS | L6: AGENDAMENTOS | M6: QUANTIDADE
B7: 1 | V7: JANEIRO
B8: 2 | V8: FEVEREIRO
B9: 3 | V9: MARÇO
B10: 4 | V10: ABRIL
B11: 5 | V11: MAIO
B12: 6 | V12: JUNHO
B13: 7 | V13: JULHO
B14: 8 | V14: AGOSTO
B15: 9 | V15: SETEMBRO
B16: 10 | V16: OUTUBRO
B17: 11 | V17: NOVEMBRO
B18: 12 | V18: DEZEMBRO
B19: 13
B20: 14
B21: 15
B22: 16
B23: 17
B24: 18
B25: 19
B26: 20
B27: 21
B28: 22
B29: 23
B30: 24
... B37: 31
B39: SEMANA 1
B41: SEMANA 2
B43: SEMANA 3
B45: TOTAL | E45: =E39+E41+E43 -> 0 | F45: =F39+F41+F43 -> 0 | G45: =G39+G41+G43 -> 0 | H45: =H39+H41+H43 -> 0 | I45: =I39+I41+I43 -> 0 | J45: =J39+J41+J43 -> 0 | K45: =K39+K41+K43 -> 0 | L45: =L39+L41+L43 -> 0 | ... N45: =N39+N41+N43 -> 0
B47: * Recomenda-se realizar o fechamento da semana toda segunda-feira.

Sheet RESUMO
A1: MÊS >>>> | B1: JULHO
A2: VENDEDOR | B2: FLUXO DE PORTA | D2: CARTEIRA | G2: LEADS | K2: VENDAS TOTAL
B3: VENDAS | C3: VISITAS | D3: VENDAS | E3: VISITAS | F3: AGENDAMENTOS | G3: VENDA | H3: VISITAS | I3: AGENDAMENTOS | J3: QUANTIDADE
A4: =VENDEDOR1!I1 -> 0 | B4: =VENDEDOR1!E45 -> 0 | C4: =VENDEDOR1!F45 -> 0 | D4: =VENDEDOR1!G45 -> 0 | E4: =VENDEDOR1!H45 -> 0 | F4: =VENDEDOR1!I45 -> 0 | G4: =VENDEDOR1!J45 -> 0 | H4: =VENDEDOR1!K45 -> 0 | I4: =VENDEDOR1!L45 -> 0 | ... K4: =VENDEDOR1!N45 -> 0
A5: =VENDEDOR2!I1 -> 0 | B5: =VENDEDOR2!E45 -> 0 | C5: =VENDEDOR2!F45 -> 0 | D5: =VENDEDOR2!G45 -> 0 | E5: =VENDEDOR2!H45 -> 0 | F5: =VENDEDOR2!I45 -> 0 | G5: =VENDEDOR2!J45 -> 0 | H5: =VENDEDOR2!K45 -> 0 | I5: =VENDEDOR2!L45 -> 0 | ... K5: =VENDEDOR2!N45 -> 0
A6: =VENDEDOR3!I1 -> 0 | B6: =VENDEDOR3!E45 -> 0 | C6: =VENDEDOR3!F45 -> 0 | D6: =VENDEDOR3!G45 -> 0 | E6: =VENDEDOR3!H45 -> 0 | F6: =VENDEDOR3!I45 -> 0 | G6: =VENDEDOR3!J45 -> 0 | H6: =VENDEDOR3!K45 -> 0 | I6: =VENDEDOR3!L45 -> 0 | ... K6: =VENDEDOR3!N45 -> 0
A7: =VENDEDOR4!I1 -> 0 | B7: =VENDEDOR4!E45 -> 0 | C7: =VENDEDOR4!F45 -> 0 | D7: =VENDEDOR4!G45 -> 0 | E7: =VENDEDOR4!H45 -> 0 | F7: =VENDEDOR4!I45 -> 0 | G7: =VENDEDOR4!J45 -> 0 | H7: =VENDEDOR4!K45 -> 0 | I7: =VENDEDOR4!L45 -> 0 | ... K7: =VENDEDOR4!N45 -> 0
A8: =VENDEDOR5!I1 -> 0 | B8: =VENDEDOR5!E45 -> 0 | C8: =VENDEDOR5!F45 -> 0 | D8: =VENDEDOR5!G45 -> 0 | E8: =VENDEDOR5!H45 -> 0 | F8: =VENDEDOR5!I45 -> 0 | G8: =VENDEDOR5!J45 -> 0 | H8: =VENDEDOR5!K45 -> 0 | I8: =VENDEDOR5!L45 -> 0 | ... K8: =VENDEDOR5!N45 -> 0
A9: =VENDEDOR6!I1 -> 0 | B9: =VENDEDOR6!E45 -> 0 | C9: =VENDEDOR6!F45 -> 0 | D9: =VENDEDOR6!G45 -> 0 | E9: =VENDEDOR6!H45 -> 0 | F9: =VENDEDOR6!I45 -> 0 | G9: =VENDEDOR6!J45 -> 0 | H9: =VENDEDOR6!K45 -> 0 | I9: =VENDEDOR6!L45 -> 0 | ... K9: =VENDEDOR6!N45 -> 0
A10: TOTAL | B10: =SUM(B4:B9) -> 0 | C10: =SUM(C4:C9) -> 0 | D10: =SUM(D4:D9) -> 0 | E10: =SUM(E4:E9) -> 0 | F10: =SUM(F4:F9) -> 0 | G10: =SUM(G4:G9) -> 0 | H10: =SUM(H4:H9) -> 0 | I10: =SUM(I4:I9) -> 0 | ... K10: =SUM(K4:K9) -> 0
A12: DEZENA >>>> | B12: DEZENA 3
A13: VENDEDOR | B13: FLUXO DE PORTA | D13: CARTEIRA | G13: LEADS | K13: VENDAS TOTAL
B14: VENDAS | C14: VISITAS | D14: VENDAS | E14: VISITAS | F14: AGENDAMENTOS | G14: VENDA | H14: VISITAS | I14: AGENDAMENTOS | J14: QUANTIDADE
A15: =A4 -> 0 | B15: =VLOOKUP($B$12,VENDEDOR1!$B$39:$N$44,4,0) -> 0 | C15: =VLOOKUP($B$12,VENDEDOR1!$B$39:$N$44,5,0) -> 0 | D15: =VLOOKUP($B$12,VENDEDOR1!$B$39:$N$44,6,0) -> 0 | E15: =VLOOKUP($B$12,VENDEDOR1!$B$39:$N$44,7,0) -> 0 | F15: =VLOOKUP($B$12,VENDEDOR1!$B$39:$N$44,8,0) -> 0 | G15: =VLOOKUP($B$12,VENDEDOR1!$B$39:$N$44,9,0) -> 0 | H15: =VLOOKUP($B$12,VENDEDOR1!$B$39:$N$44,10,0) -> 0 | I15: =VLOOKUP($B$12,VENDEDOR1!$B$39:$N$44,11,0) -> 0 | J15: =VLOOKUP($B$12,VENDEDOR1!$B$39:$N$45,12,0) -> 0 | K15: =VLOOKUP($B$12,VENDEDOR1!$B$39:$N$44,13,0) -> 0
A16: =A5 -> 0 | B16: =VLOOKUP($B$12,VENDEDOR2!$B$39:$N$44,4,0) -> 0 | C16: =VLOOKUP($B$12,VENDEDOR2!$B$39:$N$44,5,0) -> 0 | D16: =VLOOKUP($B$12,VENDEDOR2!$B$39:$N$44,6,0) -> 0 | E16: =VLOOKUP($B$12,VENDEDOR2!$B$39:$N$44,7,0) -> 0 | F16: =VLOOKUP($B$12,VENDEDOR2!$B$39:$N$44,8,0) -> 0 | G16: =VLOOKUP($B$12,VENDEDOR2!$B$39:$N$44,9,0) -> 0 | H16: =VLOOKUP($B$12,VENDEDOR2!$B$39:$N$44,10,0) -> 0 | I16: =VLOOKUP($B$12,VENDEDOR2!$B$39:$N$44,11,0) -> 0 | J16: =VLOOKUP($B$12,VENDEDOR2!$B$39:$N$45,12,0) -> 0 | K16: =VLOOKUP($B$12,VENDEDOR2!$B$39:$N$44,13,0) -> 0
A17: =A6 -> 0 | B17: =VLOOKUP($B$12,VENDEDOR3!$B$39:$N$44,4,0) -> 0 | C17: =VLOOKUP($B$12,VENDEDOR3!$B$39:$N$44,5,0) -> 0 | D17: =VLOOKUP($B$12,VENDEDOR3!$B$39:$N$44,6,0) -> 0 | E17: =VLOOKUP($B$12,VENDEDOR3!$B$39:$N$44,7,0) -> 0 | F17: =VLOOKUP($B$12,VENDEDOR3!$B$39:$N$44,8,0) -> 0 | G17: =VLOOKUP($B$12,VENDEDOR3!$B$39:$N$44,9,0) -> 0 | H17: =VLOOKUP($B$12,VENDEDOR3!$B$39:$N$44,10,0) -> 0 | I17: =VLOOKUP($B$12,VENDEDOR3!$B$39:$N$44,11,0) -> 0 | J17: =VLOOKUP($B$12,VENDEDOR3!$B$39:$N$45,12,0) -> 0 | K17: =VLOOKUP($B$12,VENDEDOR3!$B$39:$N$44,13,0) -> 0
A18: =A7 -> 0 | B18: =VLOOKUP($B$12,VENDEDOR4!$B$39:$N$44,4,0) -> 0 | C18: =VLOOKUP($B$12,VENDEDOR4!$B$39:$N$44,5,0) -> 0 | D18: =VLOOKUP($B$12,VENDEDOR4!$B$39:$N$44,6,0) -> 0 | E18: =VLOOKUP($B$12,VENDEDOR4!$B$39:$N$44,7,0) -> 0 | F18: =VLOOKUP($B$12,VENDEDOR4!$B$39:$N$44,8,0) -> 0 | G18: =VLOOKUP($B$12,VENDEDOR4!$B$39:$N$44,9,0) -> 0 | H18: =VLOOKUP($B$12,VENDEDOR4!$B$39:$N$44,10,0) -> 0 | I18: =VLOOKUP($B$12,VENDEDOR4!$B$39:$N$44,11,0) -> 0 | J18: =VLOOKUP($B$12,VENDEDOR4!$B$39:$N$45,12,0) -> 0 | K18: =VLOOKUP($B$12,VENDEDOR4!$B$39:$N$44,13,0) -> 0
A19: =A8 -> 0 | B19: =VLOOKUP($B$12,VENDEDOR5!$B$39:$N$44,4,0) -> 0 | C19: =VLOOKUP($B$12,VENDEDOR5!$B$39:$N$44,5,0) -> 0 | D19: =VLOOKUP($B$12,VENDEDOR5!$B$39:$N$44,6,0) -> 0 | E19: =VLOOKUP($B$12,VENDEDOR5!$B$39:$N$44,7,0) -> 0 | F19: =VLOOKUP($B$12,VENDEDOR5!$B$39:$N$44,8,0) -> 0 | G19: =VLOOKUP($B$12,VENDEDOR5!$B$39:$N$44,9,0) -> 0 | H19: =VLOOKUP($B$12,VENDEDOR5!$B$39:$N$44,10,0) -> 0 | I19: =VLOOKUP($B$12,VENDEDOR5!$B$39:$N$44,11,0) -> 0 | J19: =VLOOKUP($B$12,VENDEDOR5!$B$39:$N$45,12,0) -> 0 | K19: =VLOOKUP($B$12,VENDEDOR5!$B$39:$N$44,13,0) -> 0
A20: =A9 -> 0 | B20: =VLOOKUP($B$12,VENDEDOR6!$B$39:$N$44,4,0) -> 0 | C20: =VLOOKUP($B$12,VENDEDOR6!$B$39:$N$44,5,0) -> 0 | D20: =VLOOKUP($B$12,VENDEDOR6!$B$39:$N$44,6,0) -> 0 | E20: =VLOOKUP($B$12,VENDEDOR6!$B$39:$N$44,7,0) -> 0 | F20: =VLOOKUP($B$12,VENDEDOR6!$B$39:$N$44,8,0) -> 0 | G20: =VLOOKUP($B$12,VENDEDOR6!$B$39:$N$44,9,0) -> 0 | H20: =VLOOKUP($B$12,VENDEDOR6!$B$39:$N$44,10,0) -> 0 | I20: =VLOOKUP($B$12,VENDEDOR6!$B$39:$N$44,11,0) -> 0 | J20: =VLOOKUP($B$12,VENDEDOR6!$B$39:$N$45,12,0) -> 0 | K20: =VLOOKUP($B$12,VENDEDOR6!$B$39:$N$44,13,0) -> 0
A21: TOTAL | B21: =SUM(B15:B20) -> 0 | C21: =SUM(C15:C20) -> 0 | D21: =SUM(D15:D20) -> 0 | E21: =SUM(E15:E20) -> 0 | F21: =SUM(F15:F20) -> 0 | G21: =SUM(G15:G20) -> 0 | H21: =SUM(H15:H20) -> 0 | I21: =SUM(I15:I20) -> 0 | ... K21: =SUM(K15:K20) -> 0
A24: DIA >>>> | B24: 2
A25: VENDEDOR | B25: FLUXO DE PORTA | D25: CARTEIRA | G25: LEADS | K25: VENDAS TOTAL
B26: VENDAS | C26: VISITAS | D26: VENDAS | E26: VISITAS | F26: AGENDAMENTOS | G26: VENDA | H26: VISITAS | I26: AGENDAMENTOS | J26: QUANTIDADE
A27: =A15 -> 0 | B27: =VLOOKUP($B$24,VENDEDOR1!$B$7:$N$37,4,0) -> 0 | C27: =VLOOKUP($B$24,VENDEDOR1!$B$7:$N$37,5,0) -> 0 | D27: =VLOOKUP($B$24,VENDEDOR1!$B$7:$N$37,6,0) -> 0 | E27: =VLOOKUP($B$24,VENDEDOR1!$B$7:$N$37,7,0) -> 0 | F27: =VLOOKUP($B$24,VENDEDOR1!$B$7:$N$37,8,0) -> 0 | G27: =VLOOKUP($B$24,VENDEDOR1!$B$7:$N$37,9,0) -> 0 | H27: =VLOOKUP($B$24,VENDEDOR1!$B$7:$N$37,10,0) -> 0 | I27: =VLOOKUP($B$24,VENDEDOR1!$B$7:$N$37,11,0) -> 0 | J27: =VLOOKUP($B$24,VENDEDOR1!$B$7:$N$37,12,0) -> 0 | K27: =VLOOKUP($B$24,VENDEDOR1!$B$7:$N$37,13,0) -> 0
A28: =A16 -> 0 | B28: =VLOOKUP($B$24,VENDEDOR2!$B$7:$N$37,4,0) -> 0 | C28: =VLOOKUP($B$24,VENDEDOR2!$B$7:$N$37,5,0) -> 0 | D28: =VLOOKUP($B$24,VENDEDOR2!$B$7:$N$37,6,0) -> 0 | E28: =VLOOKUP($B$24,VENDEDOR2!$B$7:$N$37,7,0) -> 0 | F28: =VLOOKUP($B$24,VENDEDOR2!$B$7:$N$37,8,0) -> 0 | G28: =VLOOKUP($B$24,VENDEDOR2!$B$7:$N$37,9,0) -> 0 | H28: =VLOOKUP($B$24,VENDEDOR2!$B$7:$N$37,10,0) -> 0 | I28: =VLOOKUP($B$24,VENDEDOR2!$B$7:$N$37,11,0) -> 0 | J28: =VLOOKUP($B$24,VENDEDOR2!$B$7:$N$37,12,0) -> 0 | K28: =VLOOKUP($B$24,VENDEDOR2!$B$7:$N$37,13,0) -> 0
A29: =A17 -> 0 | B29: =VLOOKUP($B$24,VENDEDOR3!$B$7:$N$37,4,0) -> 0 | C29: =VLOOKUP($B$24,VENDEDOR3!$B$7:$N$37,5,0) -> 0 | D29: =VLOOKUP($B$24,VENDEDOR3!$B$7:$N$37,6,0) -> 0 | E29: =VLOOKUP($B$24,VENDEDOR3!$B$7:$N$37,7,0) -> 0 | F29: =VLOOKUP($B$24,VENDEDOR3!$B$7:$N$37,8,0) -> 0 | G29: =VLOOKUP($B$24,VENDEDOR3!$B$7:$N$37,9,0) -> 0 | H29: =VLOOKUP($B$24,VENDEDOR3!$B$7:$N$37,10,0) -> 0 | I29: =VLOOKUP($B$24,VENDEDOR3!$B$7:$N$37,11,0) -> 0 | J29: =VLOOKUP($B$24,VENDEDOR3!$B$7:$N$37,12,0) -> 0 | K29: =VLOOKUP($B$24,VENDEDOR3!$B$7:$N$37,13,0) -> 0
A30: =A18 -> 0 | B30: =VLOOKUP($B$24,VENDEDOR4!$B$7:$N$37,4,0) -> 0 | C30: =VLOOKUP($B$24,VENDEDOR4!$B$7:$N$37,5,0) -> 0 | D30: =VLOOKUP($B$24,VENDEDOR4!$B$7:$N$37,6,0) -> 0 | E30: =VLOOKUP($B$24,VENDEDOR4!$B$7:$N$37,7,0) -> 0 | F30: =VLOOKUP($B$24,VENDEDOR4!$B$7:$N$37,8,0) -> 0 | G30: =VLOOKUP($B$24,VENDEDOR4!$B$7:$N$37,9,0) -> 0 | H30: =VLOOKUP($B$24,VENDEDOR4!$B$7:$N$37,10,0) -> 0 | I30: =VLOOKUP($B$24,VENDEDOR4!$B$7:$N$37,11,0) -> 0 | J30: =VLOOKUP($B$24,VENDEDOR4!$B$7:$N$37,12,0) -> 0 | K30: =VLOOKUP($B$24,VENDEDOR4!$B$7:$N$37,13,0) -> 0
A31: =A19 -> 0 | B31: =VLOOKUP($B$24,VENDEDOR5!$B$7:$N$37,4,0) -> 0 | C31: =VLOOKUP($B$24,VENDEDOR5!$B$7:$N$37,5,0) -> 0 | D31: =VLOOKUP($B$24,VENDEDOR5!$B$7:$N$37,6,0) -> 0 | E31: =VLOOKUP($B$24,VENDEDOR5!$B$7:$N$37,7,0) -> 0 | F31: =VLOOKUP($B$24,VENDEDOR5!$B$7:$N$37,8,0) -> 0 | G31: =VLOOKUP($B$24,VENDEDOR5!$B$7:$N$37,9,0) -> 0 | H31: =VLOOKUP($B$24,VENDEDOR5!$B$7:$N$37,10,0) -> 0 | I31: =VLOOKUP($B$24,VENDEDOR5!$B$7:$N$37,11,0) -> 0 | J31: =VLOOKUP($B$24,VENDEDOR5!$B$7:$N$37,12,0) -> 0 | K31: =VLOOKUP($B$24,VENDEDOR5!$B$7:$N$37,13,0) -> 0
A32: =A20 -> 0 | B32: =VLOOKUP($B$24,VENDEDOR6!$B$7:$N$37,4,0) -> 0 | C32: =VLOOKUP($B$24,VENDEDOR6!$B$7:$N$37,5,0) -> 0 | D32: =VLOOKUP($B$24,VENDEDOR6!$B$7:$N$37,6,0) -> 0 | E32: =VLOOKUP($B$24,VENDEDOR6!$B$7:$N$37,7,0) -> 0 | F32: =VLOOKUP($B$24,VENDEDOR6!$B$7:$N$37,8,0) -> 0 | G32: =VLOOKUP($B$24,VENDEDOR6!$B$7:$N$37,9,0) -> 0 | H32: =VLOOKUP($B$24,VENDEDOR6!$B$7:$N$37,10,0) -> 0 | I32: =VLOOKUP($B$24,VENDEDOR6!$B$7:$N$37,11,0) -> 0 | J32: =VLOOKUP($B$24,VENDEDOR6!$B$7:$N$37,12,0) -> 0 | K32: =VLOOKUP($B$24,VENDEDOR6!$B$7:$N$37,13,0) -> 0
A33: TOTAL | B33: =SUM(B27:B32) -> 0 | C33: =SUM(C27:C32) -> 0 | D33: =SUM(D27:D32) -> 0 | E33: =SUM(E27:E32) -> 0 | F33: =SUM(F27:F32) -> 0 | G33: =SUM(G27:G32) -> 0 | H33: =SUM(H27:H32) -> 0 | I33: =SUM(I27:I32) -> 0 | ... K33: =SUM(K27:K32) -> 0
A34: =TODAY() -> 45886 | K34: =C33+E33+#REF!+H33 -> #REF!
A36: DIA >>>> | B36: =DAY(A45) -> 17
A37: VENDEDOR | B37: FLUXO DE PORTA | D37: CARTEIRA | G37: LEADS | K37: VENDAS TOTAL
B38: VENDAS | C38: VISITAS | D38: VENDAS | E38: VISITAS | F38: AGENDAMENTOS | G38: VENDA | H38: VISITAS | I38: AGENDAMENTOS | J38: QUANTIDADE
A39: =A27 -> 0 | B39: =VLOOKUP($B$36,VENDEDOR1!$B$7:$N$37,4,0) -> 0 | C39: =VLOOKUP($B$36,VENDEDOR1!$B$7:$N$37,5,0) -> 0 | D39: =VLOOKUP($B$36,VENDEDOR1!$B$7:$N$37,6,0) -> 0 | E39: =VLOOKUP($B$36,VENDEDOR1!$B$7:$N$37,7,0) -> 0 | F39: =VLOOKUP($B$36,VENDEDOR1!$B$7:$N$37,8,0) -> 0 | G39: =VLOOKUP($B$36,VENDEDOR1!$B$7:$N$37,9,0) -> 0 | H39: =VLOOKUP($B$36,VENDEDOR1!$B$7:$N$37,10,0) -> 0 | I39: =VLOOKUP($B$36,VENDEDOR1!$B$7:$N$37,11,0) -> 0 | J39: =VLOOKUP($B$36,VENDEDOR1!$B$7:$N$37,12,0) -> 0 | K39: =I39+F39+C39 -> 0
A40: =A28 -> 0 | B40: =VLOOKUP($B$36,VENDEDOR2!$B$7:$N$37,4,0) -> 0 | C40: =VLOOKUP($B$36,VENDEDOR2!$B$7:$N$37,5,0) -> 0 | D40: =VLOOKUP($B$36,VENDEDOR2!$B$7:$N$37,6,0) -> 0 | E40: =VLOOKUP($B$36,VENDEDOR2!$B$7:$N$37,7,0) -> 0 | F40: =VLOOKUP($B$36,VENDEDOR2!$B$7:$N$37,8,0) -> 0 | G40: =VLOOKUP($B$36,VENDEDOR2!$B$7:$N$37,9,0) -> 0 | H40: =VLOOKUP($B$36,VENDEDOR2!$B$7:$N$37,10,0) -> 0 | I40: =VLOOKUP($B$36,VENDEDOR2!$B$7:$N$37,11,0) -> 0 | J40: =VLOOKUP($B$36,VENDEDOR2!$B$7:$N$37,12,0) -> 0 | K40: =I40+F40+C40 -> 0
A41: =A29 -> 0 | B41: =VLOOKUP($B$36,VENDEDOR3!$B$7:$N$37,4,0) -> 0 | C41: =VLOOKUP($B$36,VENDEDOR3!$B$7:$N$37,5,0) -> 0 | D41: =VLOOKUP($B$36,VENDEDOR3!$B$7:$N$37,6,0) -> 0 | E41: =VLOOKUP($B$36,VENDEDOR3!$B$7:$N$37,7,0) -> 0 | F41: =VLOOKUP($B$36,VENDEDOR3!$B$7:$N$37,8,0) -> 0 | G41: =VLOOKUP($B$36,VENDEDOR3!$B$7:$N$37,9,0) -> 0 | H41: =VLOOKUP($B$36,VENDEDOR3!$B$7:$N$37,10,0) -> 0 | I41: =VLOOKUP($B$36,VENDEDOR3!$B$7:$N$37,11,0) -> 0 | J41: =VLOOKUP($B$36,VENDEDOR3!$B$7:$N$37,12,0) -> 0 | K41: =I41+F41+C41 -> 0
A42: =A30 -> 0 | B42: =VLOOKUP($B$36,VENDEDOR4!$B$7:$N$37,4,0) -> 0 | C42: =VLOOKUP($B$36,VENDEDOR4!$B$7:$N$37,5,0) -> 0 | D42: =VLOOKUP($B$36,VENDEDOR4!$B$7:$N$37,6,0) -> 0 | E42: =VLOOKUP($B$36,VENDEDOR4!$B$7:$N$37,7,0) -> 0 | F42: =VLOOKUP($B$36,VENDEDOR4!$B$7:$N$37,8,0) -> 0 | G42: =VLOOKUP($B$36,VENDEDOR4!$B$7:$N$37,9,0) -> 0 | H42: =VLOOKUP($B$36,VENDEDOR4!$B$7:$N$37,10,0) -> 0 | I42: =VLOOKUP($B$36,VENDEDOR4!$B$7:$N$37,11,0) -> 0 | J42: =VLOOKUP($B$36,VENDEDOR4!$B$7:$N$37,12,0) -> 0 | K42: =I42+F42+C42 -> 0
A43: =A31 -> 0 | B43: =VLOOKUP($B$36,VENDEDOR5!$B$7:$N$37,4,0) -> 0 | C43: =VLOOKUP($B$36,VENDEDOR5!$B$7:$N$37,5,0) -> 0 | D43: =VLOOKUP($B$36,VENDEDOR5!$B$7:$N$37,6,0) -> 0 | E43: =VLOOKUP($B$36,VENDEDOR5!$B$7:$N$37,7,0) -> 0 | F43: =VLOOKUP($B$36,VENDEDOR5!$B$7:$N$37,8,0) -> 0 | G43: =VLOOKUP($B$36,VENDEDOR5!$B$7:$N$37,9,0) -> 0 | H43: =VLOOKUP($B$36,VENDEDOR5!$B$7:$N$37,10,0) -> 0 | I43: =VLOOKUP($B$36,VENDEDOR5!$B$7:$N$37,11,0) -> 0 | J43: =VLOOKUP($B$36,VENDEDOR5!$B$7:$N$37,12,0) -> 0 | K43: =I43+F43+C43 -> 0
A44: =A32 -> 0 | B44: =VLOOKUP($B$36,VENDEDOR6!$B$7:$N$37,4,0) -> 0 | C44: =VLOOKUP($B$36,VENDEDOR6!$B$7:$N$37,5,0) -> 0 | D44: =VLOOKUP($B$36,VENDEDOR6!$B$7:$N$37,6,0) -> 0 | E44: =VLOOKUP($B$36,VENDEDOR6!$B$7:$N$37,7,0) -> 0 | F44: =VLOOKUP($B$36,VENDEDOR6!$B$7:$N$37,8,0) -> 0 | G44: =VLOOKUP($B$36,VENDEDOR6!$B$7:$N$37,9,0) -> 0 | H44: =VLOOKUP($B$36,VENDEDOR6!$B$7:$N$37,10,0) -> 0 | I44: =VLOOKUP($B$36,VENDEDOR6!$B$7:$N$37,11,0) -> 0 | J44: =VLOOKUP($B$36,VENDEDOR6!$B$7:$N$37,12,0) -> 0 | K44: =I44+F44+C44 -> 0
...

Sheet VENDEDOR1
B1: CONSULTOR DE VENDAS:
B3: MÊS REFERÊNCIA
B5: DIA | E5: FLUXO DE PORTA | G5: CARTEIRA | J5: LEADS | N5: VENDAS TOTAL
E6: VENDAS | F6: VISITAS | G6: VENDAS | H6: VISITA | I6: AGENDAMENTOS | J6: VENDA | K6: VISITAS | L6: AGENDAMENTO | M6: QUANTIDADE
B7: 1 | N7: =G7+E7+J7 -> 0 | V7: JANEIRO
B8: 2 | N8: =G8+E8+J8 -> 0 | V8: FEVEREIRO
B9: 3 | N9: =G9+E9+J9 -> 0 | V9: MARÇO
B10: 4 | N10: =G10+E10+J10 -> 0 | V10: ABRIL
B11: 5 | N11: =G11+E11+J11 -> 0 | V11: MAIO
B12: 6 | N12: =G12+E12+J12 -> 0 | V12: JUNHO
B13: 7 | N13: =G13+E13+J13 -> 0 | V13: JULHO
B14: 8 | N14: =G14+E14+J14 -> 0 | V14: AGOSTO
B15: 9 | N15: =G15+E15+J15 -> 0 | V15: SETEMBRO
B16: 10 | N16: =G16+E16+J16 -> 0 | V16: OUTUBRO
B17: 11 | N17: =G17+E17+J17 -> 0 | V17: NOVEMBRO
B18: 12 | N18: =G18+E18+J18 -> 0 | V18: DEZEMBRO
B19: 13 | N19: =G19+E19+J19 -> 0
B20: 14 | N20: =G20+E20+J20 -> 0
B21: 15 | N21: =G21+E21+J21 -> 0
B22: 16 | N22: =G22+E22+J22 -> 0
B23: 17 | N23: =G23+E23+J23 -> 0
B24: 18 | N24: =G24+E24+J24 -> 0
B25: 19 | N25: =G25+E25+J25 -> 0
B26: 20 | N26: =G26+E26+J26 -> 0
B27: 21 | N27: =G27+E27+J27 -> 0
B28: 22 | N28: =G28+E28+J28 -> 0
B29: 23 | N29: =G29+E29+J29 -> 0
B30: 24 | N30: =G30+E30+J30 -> 0
... B37: 31 | N37: =G37+E37+J37 -> 0
B39: DEZENA 1 | E39: =SUM(E7:E16) -> 0 | F39: =SUM(F7:F16) -> 0 | G39: =SUM(G7:G16) -> 0 | H39: =SUM(H7:H16) -> 0 | I39: =SUM(I7:I16) -> 0 | J39: =SUM(J7:J16) -> 0 | K39: =SUM(K7:K16) -> 0 | L39: =SUM(L7:L16) -> 0 | ... N39: =SUM(N7:N16) -> 0
B41: DEZENA 2 | E41: =SUM(E17:E26) -> 0 | F41: =SUM(F17:F26) -> 0 | G41: =SUM(G17:G26) -> 0 | H41: =SUM(H17:H26) -> 0 | I41: =SUM(I17:I26) -> 0 | J41: =SUM(J17:J26) -> 0 | K41: =SUM(K17:K26) -> 0 | L41: =SUM(L17:L26) -> 0 | ... N41: =SUM(N17:N26) -> 0
B43: DEZENA 3 | E43: =SUM(E27:E37) -> 0 | F43: =SUM(F27:F37) -> 0 | G43: =SUM(G27:G37) -> 0 | H43: =SUM(H27:H37) -> 0 | I43: =SUM(I27:I37) -> 0 | J43: =SUM(J27:J37) -> 0 | K43: =SUM(K27:K37) -> 0 | L43: =SUM(L27:L37) -> 0 | ... N43: =SUM(N27:N37) -> 0
B45: TOTAL | E45: =E39+E41+E43 -> 0 | F45: =F39+F41+F43 -> 0 | G45: =G39+G41+G43 -> 0 | H45: =H39+H41+H43 -> 0 | I45: =I39+I41+I43 -> 0 | J45: =J39+J41+J43 -> 0 | K45: =K39+K41+K43 -> 0 | L45: =L39+L41+L43 -> 0 | ... N45: =N39+N41+N43 -> 0
B47: * Realizar o FEEDBACK ESTRUTURADO com o vendedor ao final de cada dezena.

Sheet VENDEDOR2
B1: CONSULTOR DE VENDAS:
B3: MÊS REFERÊNCIA
B5: DIA | E5: FLUXO DE PORTA | G5: CARTEIRA | J5: LEADS | N5: VENDAS TOTAL
E6: VENDAS | F6: VISITAS | G6: VENDAS | H6: VISITA | I6: AGENDAMENTOS | J6: VENDA | K6: VISITAS | L6: AGENDAMENTO | M6: QUANTIDADE
B7: 1 | N7: =G7+E7+J7 -> 0 | V7: JANEIRO
B8: 2 | N8: =G8+E8+J8 -> 0 | V8: FEVEREIRO
B9: 3 | N9: =G9+E9+J9 -> 0 | V9: MARÇO
B10: 4 | N10: =G10+E10+J10 -> 0 | V10: ABRIL
B11: 5 | N11: =G11+E11+J11 -> 0 | V11: MAIO
B12: 6 | N12: =G12+E12+J12 -> 0 | V12: JUNHO
B13: 7 | N13: =G13+E13+J13 -> 0 | V13: JULHO
B14: 8 | N14: =G14+E14+J14 -> 0 | V14: AGOSTO
B15: 9 | N15: =G15+E15+J15 -> 0 | V15: SETEMBRO
B16: 10 | N16: =G16+E16+J16 -> 0 | V16: OUTUBRO
B17: 11 | N17: =G17+E17+J17 -> 0 | V17: NOVEMBRO
B18: 12 | N18: =G18+E18+J18 -> 0 | V18: DEZEMBRO
B19: 13 | N19: =G19+E19+J19 -> 0
B20: 14 | N20: =G20+E20+J20 -> 0
B21: 15 | N21: =G21+E21+J21 -> 0
B22: 16 | N22: =G22+E22+J22 -> 0
B23: 17 | N23: =G23+E23+J23 -> 0
B24: 18 | N24: =G24+E24+J24 -> 0
B25: 19 | N25: =G25+E25+J25 -> 0
B26: 20 | N26: =G26+E26+J26 -> 0
B27: 21 | N27: =G27+E27+J27 -> 0
B28: 22 | N28: =G28+E28+J28 -> 0
B29: 23 | N29: =G29+E29+J29 -> 0
B30: 24 | N30: =G30+E30+J30 -> 0
... B37: 31 | N37: =G37+E37+J37 -> 0
B39: DEZENA 1 | E39: =SUM(E7:E16) -> 0 | F39: =SUM(F7:F16) -> 0 | G39: =SUM(G7:G16) -> 0 | H39: =SUM(H7:H16) -> 0 | I39: =SUM(I7:I16) -> 0 | J39: =SUM(J7:J16) -> 0 | K39: =SUM(K7:K16) -> 0 | L39: =SUM(L7:L16) -> 0 | ... N39: =SUM(N7:N16) -> 0
B41: DEZENA 2 | E41: =SUM(E17:E26) -> 0 | F41: =SUM(F17:F26) -> 0 | G41: =SUM(G17:G26) -> 0 | H41: =SUM(H17:H26) -> 0 | I41: =SUM(I17:I26) -> 0 | J41: =SUM(J17:J26) -> 0 | K41: =SUM(K17:K26) -> 0 | L41: =SUM(L17:L26) -> 0 | ... N41: =SUM(N17:N26) -> 0
B43: DEZENA 3 | E43: =SUM(E27:E37) -> 0 | F43: =SUM(F27:F37) -> 0 | G43: =SUM(G27:G37) -> 0 | H43: =SUM(H27:H37) -> 0 | I43: =SUM(I27:I37) -> 0 | J43: =SUM(J27:J37) -> 0 | K43: =SUM(K27:K37) -> 0 | L43: =SUM(L27:L37) -> 0 | ... N43: =SUM(N27:N37) -> 0
B45: TOTAL | E45: =E39+E41+E43 -> 0 | F45: =F39+F41+F43 -> 0 | G45: =G39+G41+G43 -> 0 | H45: =H39+H41+H43 -> 0 | I45: =I39+I41+I43 -> 0 | J45: =J39+J41+J43 -> 0 | K45: =K39+K41+K43 -> 0 | L45: =L39+L41+L43 -> 0 | ... N45: =N39+N41+N43 -> 0
B47: * Realizar o FEEDBACK ESTRUTURADO com o vendedor ao final de cada dezena.

Sheet VENDEDOR3
B1: CONSULTOR DE VENDAS:
B3: MÊS REFERÊNCIA
B5: DIA | E5: FLUXO DE PORTA | G5: CARTEIRA | J5: LEADS | N5: VENDAS TOTAL
E6: VENDAS | F6: VISITAS | G6: VENDAS | H6: VISITA | I6: AGENDAMENTOS | J6: VENDA | K6: VISITAS | L6: AGENDAMENTO | M6: QUANTIDADE
B7: 1 | N7: =G7+E7+J7 -> 0 | V7: JANEIRO
B8: 2 | N8: =G8+E8+J8 -> 0 | V8: FEVEREIRO
B9: 3 | N9: =G9+E9+J9 -> 0 | V9: MARÇO
B10: 4 | N10: =G10+E10+J10 -> 0 | V10: ABRIL
B11: 5 | N11: =G11+E11+J11 -> 0 | V11: MAIO
B12: 6 | N12: =G12+E12+J12 -> 0 | V12: JUNHO
B13: 7 | N13: =G13+E13+J13 -> 0 | V13: JULHO
B14: 8 | N14: =G14+E14+J14 -> 0 | V14: AGOSTO
B15: 9 | N15: =G15+E15+J15 -> 0 | V15: SETEMBRO
B16: 10 | N16: =G16+E16+J16 -> 0 | V16: OUTUBRO
B17: 11 | N17: =G17+E17+J17 -> 0 | V17: NOVEMBRO
B18: 12 | N18: =G18+E18+J18 -> 0 | V18: DEZEMBRO
B19: 13 | N19: =G19+E19+J19 -> 0
B20: 14 | N20: =G20+E20+J20 -> 0
B21: 15 | N21: =G21+E21+J21 -> 0
B22: 16 | N22: =G22+E22+J22 -> 0
B23: 17 | N23: =G23+E23+J23 -> 0
B24: 18 | N24: =G24+E24+J24 -> 0
B25: 19 | N25: =G25+E25+J25 -> 0
B26: 20 | N26: =G26+E26+J26 -> 0
B27: 21 | N27: =G27+E27+J27 -> 0
B28: 22 | N28: =G28+E28+J28 -> 0
B29: 23 | N29: =G29+E29+J29 -> 0
B30: 24 | N30: =G30+E30+J30 -> 0
... B37: 31 | N37: =G37+E37+J37 -> 0
B39: DEZENA 1 | E39: =SUM(E7:E16) -> 0 | F39: =SUM(F7:F16) -> 0 | G39: =SUM(G7:G16) -> 0 | H39: =SUM(H7:H16) -> 0 | I39: =SUM(I7:I16) -> 0 | J39: =SUM(J7:J16) -> 0 | K39: =SUM(K7:K16) -> 0 | L39: =SUM(L7:L16) -> 0 | ... N39: =SUM(N7:N16) -> 0
B41: DEZENA 2 | E41: =SUM(E17:E26) -> 0 | F41: =SUM(F17:F26) -> 0 | G41: =SUM(G17:G26) -> 0 | H41: =SUM(H17:H26) -> 0 | I41: =SUM(I17:I26) -> 0 | J41: =SUM(J17:J26) -> 0 | K41: =SUM(K17:K26) -> 0 | L41: =SUM(L17:L26) -> 0 | ... N41: =SUM(N17:N26) -> 0
B43: DEZENA 3 | E43: =SUM(E27:E37) -> 0 | F43: =SUM(F27:F37) -> 0 | G43: =SUM(G27:G37) -> 0 | H43: =SUM(H27:H37) -> 0 | I43: =SUM(I27:I37) -> 0 | J43: =SUM(J27:J37) -> 0 | K43: =SUM(K27:K37) -> 0 | L43: =SUM(L27:L37) -> 0 | ... N43: =SUM(N27:N37) -> 0
B45: TOTAL | E45: =E39+E41+E43 -> 0 | F45: =F39+F41+F43 -> 0 | G45: =G39+G41+G43 -> 0 | H45: =H39+H41+H43 -> 0 | I45: =I39+I41+I43 -> 0 | J45: =J39+J41+J43 -> 0 | K45: =K39+K41+K43 -> 0 | L45: =L39+L41+L43 -> 0 | ... N45: =N39+N41+N43 -> 0
B47: * Realizar o FEEDBACK ESTRUTURADO com o vendedor ao final de cada dezena.

Sheet VENDEDOR4
B1: CONSULTOR DE VENDAS:
B3: MÊS REFERÊNCIA
B5: DIA | E5: FLUXO DE PORTA | G5: CARTEIRA | J5: LEADS | N5: VENDAS TOTAL
E6: VENDAS | F6: VISITAS | G6: VENDAS | H6: VISITA | I6: AGENDAMENTOS | J6: VENDA | K6: VISITAS | L6: AGENDAMENTO | M6: QUANTIDADE
B7: 1 | N7: =G7+E7+J7 -> 0 | V7: JANEIRO
B8: 2 | N8: =G8+E8+J8 -> 0 | V8: FEVEREIRO
B9: 3 | N9: =G9+E9+J9 -> 0 | V9: MARÇO
B10: 4 | N10: =G10+E10+J10 -> 0 | V10: ABRIL
B11: 5 | N11: =G11+E11+J11 -> 0 | V11: MAIO
B12: 6 | N12: =G12+E12+J12 -> 0 | V12: JUNHO
B13: 7 | N13: =G13+E13+J13 -> 0 | V13: JULHO
B14: 8 | N14: =G14+E14+J14 -> 0 | V14: AGOSTO
B15: 9 | N15: =G15+E15+J15 -> 0 | V15: SETEMBRO
B16: 10 | N16: =G16+E16+J16 -> 0 | V16: OUTUBRO
B17: 11 | N17: =G17+E17+J17 -> 0 | V17: NOVEMBRO
B18: 12 | N18: =G18+E18+J18 -> 0 | V18: DEZEMBRO
B19: 13 | N19: =G19+E19+J19 -> 0
B20: 14 | N20: =G20+E20+J20 -> 0
B21: 15 | N21: =G21+E21+J21 -> 0
B22: 16 | N22: =G22+E22+J22 -> 0
B23: 17 | N23: =G23+E23+J23 -> 0
B24: 18 | N24: =G24+E24+J24 -> 0
B25: 19 | N25: =G25+E25+J25 -> 0
B26: 20 | N26: =G26+E26+J26 -> 0
B27: 21 | N27: =G27+E27+J27 -> 0
B28: 22 | N28: =G28+E28+J28 -> 0
B29: 23 | N29: =G29+E29+J29 -> 0
B30: 24 | N30: =G30+E30+J30 -> 0
... B37: 31 | N37: =G37+E37+J37 -> 0
B39: DEZENA 1 | E39: =SUM(E7:E16) -> 0 | F39: =SUM(F7:F16) -> 0 | G39: =SUM(G7:G16) -> 0 | H39: =SUM(H7:H16) -> 0 | I39: =SUM(I7:I16) -> 0 | J39: =SUM(J7:J16) -> 0 | K39: =SUM(K7:K16) -> 0 | L39: =SUM(L7:L16) -> 0 | ... N39: =SUM(N7:N16) -> 0
B41: DEZENA 2 | E41: =SUM(E17:E26) -> 0 | F41: =SUM(F17:F26) -> 0 | G41: =SUM(G17:G26) -> 0 | H41: =SUM(H17:H26) -> 0 | I41: =SUM(I17:I26) -> 0 | J41: =SUM(J17:J26) -> 0 | K41: =SUM(K17:K26) -> 0 | L41: =SUM(L17:L26) -> 0 | ... N41: =SUM(N17:N26) -> 0
B43: DEZENA 3 | E43: =SUM(E27:E37) -> 0 | F43: =SUM(F27:F37) -> 0 | G43: =SUM(G27:G37) -> 0 | H43: =SUM(H27:H37) -> 0 | I43: =SUM(I27:I37) -> 0 | J43: =SUM(J27:J37) -> 0 | K43: =SUM(K27:K37) -> 0 | L43: =SUM(L27:L37) -> 0 | ... N43: =SUM(N27:N37) -> 0
B45: TOTAL | E45: =E39+E41+E43 -> 0 | F45: =F39+F41+F43 -> 0 | G45: =G39+G41+G43 -> 0 | H45: =H39+H41+H43 -> 0 | I45: =I39+I41+I43 -> 0 | J45: =J39+J41+J43 -> 0 | K45: =K39+K41+K43 -> 0 | L45: =L39+L41+L43 -> 0 | ... N45: =N39+N41+N43 -> 0
B47: * Realizar o FEEDBACK ESTRUTURADO com o vendedor ao final de cada dezena.

Sheet VENDEDOR5
B1: CONSULTOR DE VENDAS:
B3: MÊS REFERÊNCIA
B5: DIA | E5: FLUXO DE PORTA | G5: CARTEIRA | J5: LEADS | N5: VENDAS TOTAL
E6: VENDAS | F6: VISITAS | G6: VENDAS | H6: VISITA | I6: AGENDAMENTOS | J6: VENDA | K6: VISITAS | L6: AGENDAMENTO | M6: QUANTIDADE
B7: 1 | N7: =G7+E7+J7 -> 0 | V7: JANEIRO
B8: 2 | N8: =G8+E8+J8 -> 0 | V8: FEVEREIRO
B9: 3 | N9: =G9+E9+J9 -> 0 | V9: MARÇO
B10: 4 | N10: =G10+E10+J10 -> 0 | V10: ABRIL
B11: 5 | N11: =G11+E11+J11 -> 0 | V11: MAIO
B12: 6 | N12: =G12+E12+J12 -> 0 | V12: JUNHO
B13: 7 | N13: =G13+E13+J13 -> 0 | V13: JULHO
B14: 8 | N14: =G14+E14+J14 -> 0 | V14: AGOSTO
B15: 9 | N15: =G15+E15+J15 -> 0 | V15: SETEMBRO
B16: 10 | N16: =G16+E16+J16 -> 0 | V16: OUTUBRO
B17: 11 | N17: =G17+E17+J17 -> 0 | V17: NOVEMBRO
B18: 12 | N18: =G18+E18+J18 -> 0 | V18: DEZEMBRO
B19: 13 | N19: =G19+E19+J19 -> 0
B20: 14 | N20: =G20+E20+J20 -> 0
B21: 15 | N21: =G21+E21+J21 -> 0
B22: 16 | N22: =G22+E22+J22 -> 0
B23: 17 | N23: =G23+E23+J23 -> 0
B24: 18 | N24: =G24+E24+J24 -> 0
B25: 19 | N25: =G25+E25+J25 -> 0
B26: 20 | N26: =G26+E26+J26 -> 0
B27: 21 | N27: =G27+E27+J27 -> 0
B28: 22 | N28: =G28+E28+J28 -> 0
B29: 23 | N29: =G29+E29+J29 -> 0
B30: 24 | N30: =G30+E30+J30 -> 0
... B37: 31 | N37: =G37+E37+J37 -> 0
B39: DEZENA 1 | E39: =SUM(E7:E16) -> 0 | F39: =SUM(F7:F16) -> 0 | G39: =SUM(G7:G16) -> 0 | H39: =SUM(H7:H16) -> 0 | I39: =SUM(I7:I16) -> 0 | J39: =SUM(J7:J16) -> 0 | K39: =SUM(K7:K16) -> 0 | L39: =SUM(L7:L16) -> 0 | ... N39: =SUM(N7:N16) -> 0
B41: DEZENA 2 | E41: =SUM(E17:E26) -> 0 | F41: =SUM(F17:F26) -> 0 | G41: =SUM(G17:G26) -> 0 | H41: =SUM(H17:H26) -> 0 | I41: =SUM(I17:I26) -> 0 | J41: =SUM(J17:J26) -> 0 | K41: =SUM(K17:K26) -> 0 | L41: =SUM(L17:L26) -> 0 | ... N41: =SUM(N17:N26) -> 0
B43: DEZENA 3 | E43: =SUM(E27:E37) -> 0 | F43: =SUM(F27:F37) -> 0 | G43: =SUM(G27:G37) -> 0 | H43: =SUM(H27:H37) -> 0 | I43: =SUM(I27:I37) -> 0 | J43: =SUM(J27:J37) -> 0 | K43: =SUM(K27:K37) -> 0 | L43: =SUM(L27:L37) -> 0 | ... N43: =SUM(N27:N37) -> 0
B45: TOTAL | E45: =E39+E41+E43 -> 0 | F45: =F39+F41+F43 -> 0 | G45: =G39+G41+G43 -> 0 | H45: =H39+H41+H43 -> 0 | I45: =I39+I41+I43 -> 0 | J45: =J39+J41+J43 -> 0 | K45: =K39+K41+K43 -> 0 | L45: =L39+L41+L43 -> 0 | ... N45: =N39+N41+N43 -> 0
B47: * Realizar o FEEDBACK ESTRUTURADO com o vendedor ao final de cada dezena.

Sheet VENDEDOR6
B1: CONSULTOR DE VENDAS:
B3: MÊS REFERÊNCIA
B5: DIA | E5: FLUXO DE PORTA | G5: CARTEIRA | J5: LEADS | N5: VENDAS TOTAL
E6: VENDAS | F6: VISITAS | G6: VENDAS | H6: VISITA | I6: AGENDAMENTOS | J6: VENDA | K6: VISITAS | L6: AGENDAMENTO | M6: QUANTIDADE
B7: 1 | N7: =G7+E7+J7 -> 0 | V7: JANEIRO
B8: 2 | N8: =G8+E8+J8 -> 0 | V8: FEVEREIRO
B9: 3 | N9: =G9+E9+J9 -> 0 | V9: MARÇO
B10: 4 | N10: =G10+E10+J10 -> 0 | V10: ABRIL
B11: 5 | N11: =G11+E11+J11 -> 0 | V11: MAIO
B12: 6 | N12: =G12+E12+J12 -> 0 | V12: JUNHO
B13: 7 | N13: =G13+E13+J13 -> 0 | V13: JULHO
B14: 8 | N14: =G14+E14+J14 -> 0 | V14: AGOSTO
B15: 9 | N15: =G15+E15+J15 -> 0 | V15: SETEMBRO
B16: 10 | N16: =G16+E16+J16 -> 0 | V16: OUTUBRO
B17: 11 | N17: =G17+E17+J17 -> 0 | V17: NOVEMBRO
B18: 12 | N18: =G18+E18+J18 -> 0 | V18: DEZEMBRO
B19: 13 | N19: =G19+E19+J19 -> 0
B20: 14 | N20: =G20+E20+J20 -> 0
B21: 15 | N21: =G21+E21+J21 -> 0
B22: 16 | N22: =G22+E22+J22 -> 0
B23: 17 | N23: =G23+E23+J23 -> 0
B24: 18 | N24: =G24+E24+J24 -> 0
B25: 19 | N25: =G25+E25+J25 -> 0
B26: 20 | N26: =G26+E26+J26 -> 0
B27: 21 | N27: =G27+E27+J27 -> 0
B28: 22 | N28: =G28+E28+J28 -> 0
B29: 23 | N29: =G29+E29+J29 -> 0
B30: 24 | N30: =G30+E30+J30 -> 0
... B37: 31 | N37: =G37+E37+J37 -> 0
B39: DEZENA 1 | E39: =SUM(E7:E16) -> 0 | F39: =SUM(F7:F16) -> 0 | G39: =SUM(G7:G16) -> 0 | H39: =SUM(H7:H16) -> 0 | I39: =SUM(I7:I16) -> 0 | J39: =SUM(J7:J16) -> 0 | K39: =SUM(K7:K16) -> 0 | L39: =SUM(L7:L16) -> 0 | ... N39: =SUM(N7:N16) -> 0
B41: DEZENA 2 | E41: =SUM(E17:E26) -> 0 | F41: =SUM(F17:F26) -> 0 | G41: =SUM(G17:G26) -> 0 | H41: =SUM(H17:H26) -> 0 | I41: =SUM(I17:I26) -> 0 | J41: =SUM(J17:J26) -> 0 | K41: =SUM(K17:K26) -> 0 | L41: =SUM(L17:L26) -> 0 | ... N41: =SUM(N17:N26) -> 0
B43: DEZENA 3 | E43: =SUM(E27:E37) -> 0 | F43: =SUM(F27:F37) -> 0 | G43: =SUM(G27:G37) -> 0 | H43: =SUM(H27:H37) -> 0 | I43: =SUM(I27:I37) -> 0 | J43: =SUM(J27:J37) -> 0 | K43: =SUM(K27:K37) -> 0 | L43: =SUM(L27:L37) -> 0 | ... N43: =SUM(N27:N37) -> 0
B45: TOTAL | E45: =E39+E41+E43 -> 0 | F45: =F39+F41+F43 -> 0 | G45: =G39+G41+G43 -> 0 | H45: =H39+H41+H43 -> 0 | I45: =I39+I41+I43 -> 0 | J45: =J39+J41+J43 -> 0 | K45: =K39+K41+K43 -> 0 | L45: =L39+L41+L43 -> 0 | ... N45: =N39+N41+N43 -> 0
B47: * Realizar o FEEDBACK ESTRUTURADO com o vendedor ao final de cada dezena.

Sheet GESTÃO A VISTA
A1: MÊS: | B1: =B3 -> 45886
A3: DIA: | B3: =TODAY() -> 45886
A5: META DO MÊS:
A7: % DA META HOJE | B7: Hoje deveríamos estar com | E7: =DAY(B3)/VLOOKUP(MONTH(B1),S11:T22,2,0) -> 0.5483871 | F7: da meta
A9: RESULTADO: | B9: =F19 -> 0
A11: VENDEDOR: | B11: META | C11: RESULTADO DE VENDAS | S11: 1 | T11: 31
C12: PORTA | D12: CARTEIRA | E12: INTERNET | F12: TOTAL | G12: % META | S12: 2 | T12: 28
A13: =RESUMO!A4 -> 0 | B13: 6 | C13: =VLOOKUP(A13,RESUMO!$A$4:$K$9,2,0) -> 0 | D13: =VLOOKUP(A13,RESUMO!$A$4:$K$9,4,0) -> 0 | E13: =VLOOKUP(A13,RESUMO!$A$4:$K$9,7,0) -> 0 | F13: =SUM(C13:E13) -> 0 | G13: =IFERROR(F13/B13,"") -> 0 | S13: 3 | T13: 31
A14: =RESUMO!A5 -> 0 | B14: 6 | C14: =VLOOKUP(A14,RESUMO!$A$4:$K$9,2,0) -> 0 | D14: =VLOOKUP(A14,RESUMO!$A$4:$K$9,4,0) -> 0 | E14: =VLOOKUP(A14,RESUMO!$A$4:$K$9,7,0) -> 0 | F14: =SUM(C14:E14) -> 0 | G14: =IFERROR(F14/B14,"") -> 0 | S14: 4 | T14: 30
A15: =RESUMO!A6 -> 0 | B15: 6 | C15: =VLOOKUP(A15,RESUMO!$A$4:$K$9,2,0) -> 0 | D15: =VLOOKUP(A15,RESUMO!$A$4:$K$9,4,0) -> 0 | E15: =VLOOKUP(A15,RESUMO!$A$4:$K$9,7,0) -> 0 | F15: =SUM(C15:E15) -> 0 | G15: =IFERROR(F15/B15,"") -> 0 | S15: 5 | T15: 31
A16: =RESUMO!A7 -> 0 | B16: 6 | C16: =VLOOKUP(A16,RESUMO!$A$4:$K$9,2,0) -> 0 | D16: =VLOOKUP(A16,RESUMO!$A$4:$K$9,4,0) -> 0 | E16: =VLOOKUP(A16,RESUMO!$A$4:$K$9,7,0) -> 0 | F16: =SUM(C16:E16) -> 0 | G16: =IFERROR(F16/B16,"") -> 0 | S16: 6 | T16: 30
A17: =RESUMO!A8 -> 0 | C17: =VLOOKUP(A17,RESUMO!$A$4:$K$9,2,0) -> 0 | D17: =VLOOKUP(A17,RESUMO!$A$4:$K$9,4,0) -> 0 | E17: =VLOOKUP(A17,RESUMO!$A$4:$K$9,7,0) -> 0 | F17: =SUM(C17:E17) -> 0 | G17: =IFERROR(F17/B17,"") | S17: 7 | T17: 31
A18: =RESUMO!A9 -> 0 | C18: =VLOOKUP(A18,RESUMO!$A$4:$K$9,2,0) -> 0 | D18: =VLOOKUP(A18,RESUMO!$A$4:$K$9,4,0) -> 0 | E18: =VLOOKUP(A18,RESUMO!$A$4:$K$9,7,0) -> 0 | F18: =SUM(C18:E18) -> 0 | G18: =IFERROR(F18/B18,"") | S18: 8 | T18: 31
A19: TOTAL | B19: =SUM(B13:B18) -> 24 | C19: =SUM(C13:C18) -> 0 | D19: =SUM(D13:D18) -> 0 | E19: =SUM(E13:E18) -> 0 | F19: =SUM(F13:F18) -> 0 | G19: =IFERROR(F19/B19,"") -> 0 | S19: 9 | T19: 30
S20: 10 | T20: 31
A21: PERFORMANCE | B21: META | C21: NEGOCIAÇÕES NO MÊS | S21: 11 | T21: 30
C22: PORTA | D22: CARTEIRA | E22: INTERNET | F22: TOTAL | G22: % META | S22: 12 | T22: 31
A23: =A13 -> 0 | B23: =B13*5 -> 30 | C23: =VLOOKUP(A23,RESUMO!$A$4:$K$9,3,0) -> 0 | D23: =VLOOKUP(A23,RESUMO!$A$4:$K$9,5,0) -> 0 | E23: =VLOOKUP(A23,RESUMO!$A$4:$K$9,11,0) -> 0 | F23: =SUM(C23:E23) -> 0 | G23: =IFERROR(F23/B23,"") -> 0
A24: =A14 -> 0 | B24: =B14*5 -> 30 | C24: =VLOOKUP(A24,RESUMO!$A$4:$K$9,3,0) -> 0 | D24: =VLOOKUP(A24,RESUMO!$A$4:$K$9,5,0) -> 0 | E24: =VLOOKUP(A24,RESUMO!$A$4:$K$9,11,0) -> 0 | F24: =SUM(C24:E24) -> 0 | G24: =IFERROR(F24/B24,"") -> 0
A25: =A15 -> 0 | B25: =B15*5 -> 30 | C25: =VLOOKUP(A25,RESUMO!$A$4:$K$9,3,0) -> 0 | D25: =VLOOKUP(A25,RESUMO!$A$4:$K$9,5,0) -> 0 | E25: =VLOOKUP(A25,RESUMO!$A$4:$K$9,11,0) -> 0 | F25: =SUM(C25:E25) -> 0 | G25: =IFERROR(F25/B25,"") -> 0
A26: =A16 -> 0 | B26: =B16*5 -> 30 | C26: =VLOOKUP(A26,RESUMO!$A$4:$K$9,3,0) -> 0 | D26: =VLOOKUP(A26,RESUMO!$A$4:$K$9,5,0) -> 0 | E26: =VLOOKUP(A26,RESUMO!$A$4:$K$9,11,0) -> 0 | F26: =SUM(C26:E26) -> 0 | G26: =IFERROR(F26/B26,"") -> 0
A27: =A17 -> 0 | B27: =B17*5 -> 0 | C27: =VLOOKUP(A27,RESUMO!$A$4:$K$9,3,0) -> 0 | D27: =VLOOKUP(A27,RESUMO!$A$4:$K$9,5,0) -> 0 | E27: =VLOOKUP(A27,RESUMO!$A$4:$K$9,11,0) -> 0 | F27: =SUM(C27:E27) -> 0 | G27: =IFERROR(F27/B27,"")
A28: =A18 -> 0 | B28: =B18*5 -> 0 | C28: =VLOOKUP(A28,RESUMO!$A$4:$K$9,3,0) -> 0 | D28: =VLOOKUP(A28,RESUMO!$A$4:$K$9,5,0) -> 0 | E28: =VLOOKUP(A28,RESUMO!$A$4:$K$9,11,0) -> 0 | F28: =SUM(C28:E28) -> 0 | G28: =IFERROR(F28/B28,"")
A29: TOTAL | B29: =SUM(B23:B28) -> 120 | C29: =SUM(C23:C28) -> 0 | D29: =SUM(D23:D28) -> 0 | E29: =SUM(E23:E28) -> 0 | F29: =SUM(F23:F28) -> 0 | G29: =SUM(G23:G28) -> 0
A31: AGENDAMENTOS DE HOJE | B31: =VLOOKUP(B3,RESUMO!A45:K45,11,0) -> 0
